<?xml version="1.0"?>

<robot name="my_robot">
    <material name="grey">
        <color rgba="0.5 0.5 0.5 1" />
    </material>
    
    <material name="red">
        <color rgba="0.8 0 0 1" />
    </material>

    <link name="base_link">
        <visual>
            <geometry>
                <mesh filename="file:///home/me/project3_ws/Project3/project3_description/models/Robot_Base_Chasis.dae" scale="0.01 0.01 0.01"/>
            </geometry>
            <origin xyz="0 0 0.4" rpy="0 0 0" />
            <material name="grey" />
        </visual> 
        <collision>
            <geometry>
                <mesh filename="file:///home/me/project3_ws/Project3/project3_description/models/Robot_Base_Chasis.dae" scale="0.01 0.01 0.01"/>
            </geometry>
            <origin xyz="0 0 0.4" rpy="0 0 0" />
        </collision>
    </link>
    
    <link name="wheel1_link">
        <visual>
            <geometry>
                <mesh filename="file:///home/me/project3_ws/Project3/project3_description/models/Robot_Wheel.dae" scale="0.01 0.01 0.01"/>
            </geometry>
            <origin xyz="0 0 0" rpy="0 0 0" />
            <material name="red" />
        </visual>
        <collision>
            <geometry>
                <mesh filename="file:///home/me/project3_ws/Project3/project3_description/models/Robot_Wheel.dae" scale="0.01 0.01 0.01"/>
            </geometry>
            <origin xyz="0 0 0" rpy="0 0 0" />
        </collision>
    </link>
    
    <joint name="joint1" type="continuous">
        <parent link="base_link" />
        <child link="wheel1_link" />
        <origin xyz="0.8 2.0 0.9" rpy="0 0 1.57" />
        <axis xyz="0 1 0" rpy="0 0 0" />
        <limit effort="1000.0" velocity="1.0" lower="-3.14" upper="3.14" />
    </joint>
 
     <link name="wheel2_link">
        <visual>
            <geometry>
                <mesh filename="file:///home/me/project3_ws/Project3/project3_description/models/Robot_Wheel.dae" scale="0.01 0.01 0.01"/>
            </geometry>
            <origin xyz="0 0 0" rpy="0 0 0" />
            <material name="red" />
        </visual>
        <collision>
            <geometry>
                <mesh filename="file:///home/me/project3_ws/Project3/project3_description/models/Robot_Wheel.dae" scale="0.01 0.01 0.01"/>
            </geometry>
            <origin xyz="0 0 0" rpy="0 0 0" />
        </collision>
    </link>
    
    <joint name="joint2" type="continuous">
        <parent link="base_link" />
        <child link="wheel2_link" />
        <origin xyz="6.0 2.0 0.9" rpy="0 0 1.57" />
        <axis xyz="0 1 0" rpy="0 0 0" />
        <limit effort="1000.0" velocity="1.0" lower="-3.14" upper="3.14" />
    </joint>
    <link name="wheel3_link">
        <visual>
            <geometry>
                <mesh filename="file:///home/me/project3_ws/Project3/project3_description/models/Robot_Wheel.dae" scale="0.01 0.01 0.01"/>
            </geometry>
            <origin xyz="0 0 0" rpy="0 0 0" />
            <material name="red" />
        </visual>
        <collision>
            <geometry>
                <mesh filename="file:///home/me/project3_ws/Project3/project3_description/models/Robot_Wheel.dae" scale="0.01 0.01 0.01"/>
            </geometry>
            <origin xyz="0 0 0" rpy="0 0 0" />
        </collision>
    </link>
    
    <joint name="joint3" type="continuous">
        <parent link="base_link" />
        <child link="wheel3_link" />
        <origin xyz="0.8 5.0 0.9" rpy="0 0 1.57" />
        <axis xyz="0 1 0" rpy="0 0 0" />
        <limit effort="1000.0" velocity="1.0" lower="-3.14" upper="3.14" />
    </joint>
 
     <link name="wheel4_link">
        <visual>
            <geometry>
                <mesh filename="file:///home/me/project3_ws/Project3/project3_description/models/Robot_Wheel.dae" scale="0.01 0.01 0.01"/>
            </geometry>
            <origin xyz="0 0 0" rpy="0 0 0" />
            <material name="red" />
        </visual>
        <collision>
            <geometry>
                <mesh filename="file:///home/me/project3_ws/Project3/project3_description/models/Robot_Wheel.dae" scale="0.01 0.01 0.01"/>
            </geometry>
            <origin xyz="0 0 0" rpy="0 0 0" />
        </collision>
    </link>
    
    <joint name="joint4" type="continuous">
        <parent link="base_link" />
        <child link="wheel4_link" />
        <origin xyz="6.0 5.0 0.9" rpy="0 0 1.57" />
        <axis xyz="0 1 0" rpy="0 0 0" />
        <limit effort="1000.0" velocity="1.0" lower="-3.14" upper="3.14" />
    </joint>
 </robot>
